<?xml version='1.0'?>
<sdf version='1.4'>
    <model name="SphereX">
        <!-- Give the base link a unique name -->
        <link name="SphereXOuter">
            <pose>0 0 0.3 1.57 0 0</pose>
            <inertial>
                <mass>3</mass>
                <inertia>
                    <ixx>0.108</ixx>
                    <iyy>0.108</iyy>
                    <izz>0.108</izz>
                    <ixy>0</ixy>
                    <ixz>0</ixz>
                    <iyz>0</iyz> 
                </inertia> 
            </inertial>
            <visual name="bottom_visual">
                <geometry>
                    <mesh>
                        <uri>model://spherex/spherex_bot.dae</uri>
                    </mesh>
                </geometry>
            </visual>

            <visual name="top_visual">
                <geometry>
                    <mesh>
                        <uri>model://spherex/spherex_top.dae</uri>
                    </mesh>
                </geometry>
            </visual>

            <collision name="spherex_collision">
                <geometry>
                    <sphere>
                        <radius>0.25</radius>
                    </sphere>
                </geometry>
            </collision>

        </link>

        <link name="SphereXMid">
            
            <sensor type="imu" name="imu">
                <pose>0 0 0 -1.57 0 0</pose>
                <update_rate>10</update_rate>
            </sensor>
            
            <sensor type="camera" name="cam1">
                <camera>
                    <pose>0 0 0 -1.57 0 0</pose>
                    <horizontal_fov>1</horizontal_fov>
                    <image>
                        <width>320</width>
                        <height>240</height>
                    </image>
                    <clip>
                        <far>100</far>
                    </clip>
                </camera>
                <update_rate>20</update_rate>
                <always_on>1</always_on>
            </sensor>

            <sensor type="ray" name="sensor">
                <topic>~/test_topic</topic>
                <pose>0 0 0 -1.57 0 0</pose>
                <update_rate>20</update_rate>
                <ray>
                    <scan>
                        <vertical>
                            <samples>16</samples>
                            <resolution>1</resolution>
                            <min_angle>0</min_angle>
                            <max_angle>1</max_angle>
                        </vertical>
                        
                        <horizontal>
                            <samples>128</samples>
                            <resolution>1</resolution>
                            <min_angle>0.0</min_angle>
                            <max_angle>6.28</max_angle>
                        </horizontal>
                    </scan>
                    <range>
                        <min>0.28</min>
                        <max>100</max>
                        <resolution>0.02</resolution>
                    </range>
                </ray>
            </sensor>

            <pose>0 0 0.3 1.57 0 0</pose>
            <inertial>
                <mass>0.0001</mass>
                <inertia>
                    <!-- 0.0 values will crash gazebo -->
                    <ixx>0.0001</ixx>
                    <iyy>0.0001</iyy>
                    <izz>0.0001</izz>
                    <ixy>0</ixy>
                    <ixz>0</ixz>
                    <iyz>0</iyz> 
                </inertia> 
            </inertial>
            <visual name="mid_visual">
                <geometry>
                    <mesh>
                        <uri>model://spherex/spherex_mid.dae</uri>
                    </mesh>
                </geometry>
            </visual>
        </link>

        <joint name="center_pivot" type="revolute">
            <parent>SphereXOuter</parent>
            <child>SphereXMid</child>
            <axis>
                <limit>
                    <lower>0</lower>
                    <upper>10000000000000000</upper>
                </limit>
                <xyz>0 0 1</xyz>
            </axis>
        </joint>
    </model>
</sdf>
